{
 "cells": [
  {
   "attachments": {},
   "cell_type": "markdown",
   "metadata": {},
   "source": [
    "# Домашнее задание № 3"
   ]
  },
  {
   "attachments": {},
   "cell_type": "markdown",
   "metadata": {},
   "source": [
    "1. На основе word2vec/fasttext реализовать метод поиска ближайших статей\n",
    "(на вход метода должен приходить запрос (какой-то вопрос) и количество вариантов вывода к примеру 5-ть, ваш метод должен возвращать 5-ть ближайших статей к этому запросу) 2. Проверить насколько хорошо работают подходы"
   ]
  },
  {
   "cell_type": "code",
   "execution_count": 2,
   "metadata": {},
   "outputs": [
    {
     "name": "stderr",
     "output_type": "stream",
     "text": [
      "\"wget\" �� ���� ����७��� ��� ���譥�\n",
      "��������, �ᯮ��塞�� �ணࠬ��� ��� ������ 䠩���.\n"
     ]
    }
   ],
   "source": [
    "!wget https://github.com/yutkin/Lenta.Ru-News-Dataset/releases/download/v1.0/lenta-ru-news.csv.gz"
   ]
  },
  {
   "cell_type": "code",
   "execution_count": 3,
   "metadata": {},
   "outputs": [],
   "source": [
    "import pandas as pd"
   ]
  },
  {
   "cell_type": "code",
   "execution_count": 4,
   "metadata": {},
   "outputs": [
    {
     "name": "stdout",
     "output_type": "stream",
     "text": [
      "Unexpected exception formatting exception. Falling back to standard exception\n"
     ]
    },
    {
     "name": "stderr",
     "output_type": "stream",
     "text": [
      "Traceback (most recent call last):\n",
      "  File \"c:\\Users\\azhur\\AppData\\Local\\Programs\\Python\\Python310\\lib\\site-packages\\IPython\\core\\interactiveshell.py\", line 3398, in run_code\n",
      "    exec(code_obj, self.user_global_ns, self.user_ns)\n",
      "  File \"C:\\Users\\azhur\\AppData\\Local\\Temp\\ipykernel_35984\\783939561.py\", line 1, in <cell line: 1>\n",
      "    news = pd.read_csv('lenta-ru-news.csv.gz')\n",
      "  File \"c:\\Users\\azhur\\AppData\\Local\\Programs\\Python\\Python310\\lib\\site-packages\\pandas\\util\\_decorators.py\", line 311, in wrapper\n",
      "    return func(*args, **kwargs)\n",
      "  File \"c:\\Users\\azhur\\AppData\\Local\\Programs\\Python\\Python310\\lib\\site-packages\\pandas\\io\\parsers\\readers.py\", line 680, in read_csv\n",
      "    return _read(filepath_or_buffer, kwds)\n",
      "  File \"c:\\Users\\azhur\\AppData\\Local\\Programs\\Python\\Python310\\lib\\site-packages\\pandas\\io\\parsers\\readers.py\", line 575, in _read\n",
      "    parser = TextFileReader(filepath_or_buffer, **kwds)\n",
      "  File \"c:\\Users\\azhur\\AppData\\Local\\Programs\\Python\\Python310\\lib\\site-packages\\pandas\\io\\parsers\\readers.py\", line 933, in __init__\n",
      "    self._engine = self._make_engine(f, self.engine)\n",
      "  File \"c:\\Users\\azhur\\AppData\\Local\\Programs\\Python\\Python310\\lib\\site-packages\\pandas\\io\\parsers\\readers.py\", line 1217, in _make_engine\n",
      "    self.handles = get_handle(  # type: ignore[call-overload]\n",
      "  File \"c:\\Users\\azhur\\AppData\\Local\\Programs\\Python\\Python310\\lib\\site-packages\\pandas\\io\\common.py\", line 714, in get_handle\n",
      "    handle = gzip.GzipFile(  # type: ignore[assignment]\n",
      "  File \"c:\\Users\\azhur\\AppData\\Local\\Programs\\Python\\Python310\\lib\\gzip.py\", line 174, in __init__\n",
      "    fileobj = self.myfileobj = builtins.open(filename, mode or 'rb')\n",
      "FileNotFoundError: [Errno 2] No such file or directory: 'lenta-ru-news.csv.gz'\n",
      "\n",
      "During handling of the above exception, another exception occurred:\n",
      "\n",
      "Traceback (most recent call last):\n",
      "  File \"c:\\Users\\azhur\\AppData\\Local\\Programs\\Python\\Python310\\lib\\site-packages\\IPython\\core\\interactiveshell.py\", line 1993, in showtraceback\n",
      "    stb = self.InteractiveTB.structured_traceback(\n",
      "  File \"c:\\Users\\azhur\\AppData\\Local\\Programs\\Python\\Python310\\lib\\site-packages\\IPython\\core\\ultratb.py\", line 1118, in structured_traceback\n",
      "    return FormattedTB.structured_traceback(\n",
      "  File \"c:\\Users\\azhur\\AppData\\Local\\Programs\\Python\\Python310\\lib\\site-packages\\IPython\\core\\ultratb.py\", line 1012, in structured_traceback\n",
      "    return VerboseTB.structured_traceback(\n",
      "  File \"c:\\Users\\azhur\\AppData\\Local\\Programs\\Python\\Python310\\lib\\site-packages\\IPython\\core\\ultratb.py\", line 865, in structured_traceback\n",
      "    formatted_exception = self.format_exception_as_a_whole(etype, evalue, etb, number_of_lines_of_context,\n",
      "  File \"c:\\Users\\azhur\\AppData\\Local\\Programs\\Python\\Python310\\lib\\site-packages\\IPython\\core\\ultratb.py\", line 799, in format_exception_as_a_whole\n",
      "    self.get_records(etb, number_of_lines_of_context, tb_offset) if etb else []\n",
      "  File \"c:\\Users\\azhur\\AppData\\Local\\Programs\\Python\\Python310\\lib\\site-packages\\IPython\\core\\ultratb.py\", line 845, in get_records\n",
      "    style = stack_data.style_with_executing_node(style, \"bg:ansiyellow\")\n",
      "  File \"c:\\Users\\azhur\\AppData\\Local\\Programs\\Python\\Python310\\lib\\site-packages\\stack_data\\core.py\", line 424, in style_with_executing_node\n",
      "    class NewStyle(style):\n",
      "  File \"c:\\Users\\azhur\\AppData\\Local\\Programs\\Python\\Python310\\lib\\site-packages\\pygments\\style.py\", line 91, in __new__\n",
      "    ndef[4] = colorformat(styledef[3:])\n",
      "  File \"c:\\Users\\azhur\\AppData\\Local\\Programs\\Python\\Python310\\lib\\site-packages\\pygments\\style.py\", line 58, in colorformat\n",
      "    assert False, \"wrong color format %r\" % text\n",
      "AssertionError: wrong color format 'ansiyellow'\n"
     ]
    }
   ],
   "source": [
    "news = pd.read_csv('lenta-ru-news.csv.gz')\n",
    "news"
   ]
  },
  {
   "cell_type": "code",
   "execution_count": 5,
   "metadata": {},
   "outputs": [
    {
     "name": "stdout",
     "output_type": "stream",
     "text": [
      "Requirement already satisfied: pymorphy2 in c:\\users\\azhur\\appdata\\local\\programs\\python\\python310\\lib\\site-packages (0.9.1)\n",
      "Requirement already satisfied: dawg-python>=0.7.1 in c:\\users\\azhur\\appdata\\local\\programs\\python\\python310\\lib\\site-packages (from pymorphy2) (0.7.2)\n",
      "Requirement already satisfied: pymorphy2-dicts-ru<3.0,>=2.4 in c:\\users\\azhur\\appdata\\local\\programs\\python\\python310\\lib\\site-packages (from pymorphy2) (2.4.417127.4579844)\n",
      "Requirement already satisfied: docopt>=0.6 in c:\\users\\azhur\\appdata\\local\\programs\\python\\python310\\lib\\site-packages (from pymorphy2) (0.6.2)\n"
     ]
    },
    {
     "name": "stderr",
     "output_type": "stream",
     "text": [
      "WARNING: You are using pip version 22.0.4; however, version 23.1.2 is available.\n",
      "You should consider upgrading via the 'C:\\Users\\azhur\\AppData\\Local\\Programs\\Python\\Python310\\python.exe -m pip install --upgrade pip' command.\n"
     ]
    }
   ],
   "source": [
    "!pip install pymorphy2"
   ]
  },
  {
   "cell_type": "code",
   "execution_count": 6,
   "metadata": {},
   "outputs": [
    {
     "name": "stdout",
     "output_type": "stream",
     "text": [
      "Unexpected exception formatting exception. Falling back to standard exception\n"
     ]
    },
    {
     "name": "stderr",
     "output_type": "stream",
     "text": [
      "Traceback (most recent call last):\n",
      "  File \"c:\\Users\\azhur\\AppData\\Local\\Programs\\Python\\Python310\\lib\\site-packages\\IPython\\core\\interactiveshell.py\", line 3398, in run_code\n",
      "    exec(code_obj, self.user_global_ns, self.user_ns)\n",
      "  File \"C:\\Users\\azhur\\AppData\\Local\\Temp\\ipykernel_35984\\3127552054.py\", line 4, in <cell line: 4>\n",
      "    import annoy\n",
      "ModuleNotFoundError: No module named 'annoy'\n",
      "\n",
      "During handling of the above exception, another exception occurred:\n",
      "\n",
      "Traceback (most recent call last):\n",
      "  File \"c:\\Users\\azhur\\AppData\\Local\\Programs\\Python\\Python310\\lib\\site-packages\\IPython\\core\\interactiveshell.py\", line 1993, in showtraceback\n",
      "    stb = self.InteractiveTB.structured_traceback(\n",
      "  File \"c:\\Users\\azhur\\AppData\\Local\\Programs\\Python\\Python310\\lib\\site-packages\\IPython\\core\\ultratb.py\", line 1118, in structured_traceback\n",
      "    return FormattedTB.structured_traceback(\n",
      "  File \"c:\\Users\\azhur\\AppData\\Local\\Programs\\Python\\Python310\\lib\\site-packages\\IPython\\core\\ultratb.py\", line 1012, in structured_traceback\n",
      "    return VerboseTB.structured_traceback(\n",
      "  File \"c:\\Users\\azhur\\AppData\\Local\\Programs\\Python\\Python310\\lib\\site-packages\\IPython\\core\\ultratb.py\", line 865, in structured_traceback\n",
      "    formatted_exception = self.format_exception_as_a_whole(etype, evalue, etb, number_of_lines_of_context,\n",
      "  File \"c:\\Users\\azhur\\AppData\\Local\\Programs\\Python\\Python310\\lib\\site-packages\\IPython\\core\\ultratb.py\", line 799, in format_exception_as_a_whole\n",
      "    self.get_records(etb, number_of_lines_of_context, tb_offset) if etb else []\n",
      "  File \"c:\\Users\\azhur\\AppData\\Local\\Programs\\Python\\Python310\\lib\\site-packages\\IPython\\core\\ultratb.py\", line 845, in get_records\n",
      "    style = stack_data.style_with_executing_node(style, \"bg:ansiyellow\")\n",
      "  File \"c:\\Users\\azhur\\AppData\\Local\\Programs\\Python\\Python310\\lib\\site-packages\\stack_data\\core.py\", line 424, in style_with_executing_node\n",
      "    class NewStyle(style):\n",
      "  File \"c:\\Users\\azhur\\AppData\\Local\\Programs\\Python\\Python310\\lib\\site-packages\\pygments\\style.py\", line 91, in __new__\n",
      "    ndef[4] = colorformat(styledef[3:])\n",
      "  File \"c:\\Users\\azhur\\AppData\\Local\\Programs\\Python\\Python310\\lib\\site-packages\\pygments\\style.py\", line 58, in colorformat\n",
      "    assert False, \"wrong color format %r\" % text\n",
      "AssertionError: wrong color format 'ansiyellow'\n"
     ]
    }
   ],
   "source": [
    "import string\n",
    "from pymorphy2 import MorphAnalyzer\n",
    "from stop_words import get_stop_words\n",
    "import annoy\n",
    "from gensim.models import Word2Vec, FastText\n",
    "import pickle\n",
    "import numpy as np\n",
    "from tqdm import tqdm_notebook\n",
    "import tqdm"
   ]
  },
  {
   "cell_type": "code",
   "execution_count": 7,
   "metadata": {},
   "outputs": [
    {
     "name": "stdout",
     "output_type": "stream",
     "text": [
      "Unexpected exception formatting exception. Falling back to standard exception\n"
     ]
    },
    {
     "name": "stderr",
     "output_type": "stream",
     "text": [
      "Traceback (most recent call last):\n",
      "  File \"c:\\Users\\azhur\\AppData\\Local\\Programs\\Python\\Python310\\lib\\site-packages\\IPython\\core\\interactiveshell.py\", line 3398, in run_code\n",
      "    exec(code_obj, self.user_global_ns, self.user_ns)\n",
      "  File \"C:\\Users\\azhur\\AppData\\Local\\Temp\\ipykernel_35984\\1009217653.py\", line 1, in <cell line: 1>\n",
      "    list_news = news.text.to_list()\n",
      "NameError: name 'news' is not defined\n",
      "\n",
      "During handling of the above exception, another exception occurred:\n",
      "\n",
      "Traceback (most recent call last):\n",
      "  File \"c:\\Users\\azhur\\AppData\\Local\\Programs\\Python\\Python310\\lib\\site-packages\\IPython\\core\\interactiveshell.py\", line 1993, in showtraceback\n",
      "    stb = self.InteractiveTB.structured_traceback(\n",
      "  File \"c:\\Users\\azhur\\AppData\\Local\\Programs\\Python\\Python310\\lib\\site-packages\\IPython\\core\\ultratb.py\", line 1118, in structured_traceback\n",
      "    return FormattedTB.structured_traceback(\n",
      "  File \"c:\\Users\\azhur\\AppData\\Local\\Programs\\Python\\Python310\\lib\\site-packages\\IPython\\core\\ultratb.py\", line 1012, in structured_traceback\n",
      "    return VerboseTB.structured_traceback(\n",
      "  File \"c:\\Users\\azhur\\AppData\\Local\\Programs\\Python\\Python310\\lib\\site-packages\\IPython\\core\\ultratb.py\", line 865, in structured_traceback\n",
      "    formatted_exception = self.format_exception_as_a_whole(etype, evalue, etb, number_of_lines_of_context,\n",
      "  File \"c:\\Users\\azhur\\AppData\\Local\\Programs\\Python\\Python310\\lib\\site-packages\\IPython\\core\\ultratb.py\", line 799, in format_exception_as_a_whole\n",
      "    self.get_records(etb, number_of_lines_of_context, tb_offset) if etb else []\n",
      "  File \"c:\\Users\\azhur\\AppData\\Local\\Programs\\Python\\Python310\\lib\\site-packages\\IPython\\core\\ultratb.py\", line 845, in get_records\n",
      "    style = stack_data.style_with_executing_node(style, \"bg:ansiyellow\")\n",
      "  File \"c:\\Users\\azhur\\AppData\\Local\\Programs\\Python\\Python310\\lib\\site-packages\\stack_data\\core.py\", line 424, in style_with_executing_node\n",
      "    class NewStyle(style):\n",
      "  File \"c:\\Users\\azhur\\AppData\\Local\\Programs\\Python\\Python310\\lib\\site-packages\\pygments\\style.py\", line 91, in __new__\n",
      "    ndef[4] = colorformat(styledef[3:])\n",
      "  File \"c:\\Users\\azhur\\AppData\\Local\\Programs\\Python\\Python310\\lib\\site-packages\\pygments\\style.py\", line 58, in colorformat\n",
      "    assert False, \"wrong color format %r\" % text\n",
      "AssertionError: wrong color format 'ansiyellow'\n"
     ]
    }
   ],
   "source": [
    "list_news = news.text.to_list()\n",
    "list_news[:2]"
   ]
  },
  {
   "cell_type": "code",
   "execution_count": 8,
   "metadata": {},
   "outputs": [],
   "source": [
    "def preprocess_txt(line):\n",
    "    spls = \"\".join(i for i in line.strip() if i not in exclude).split()\n",
    "    spls = [morpher.parse(i.lower())[0].normal_form for i in spls]\n",
    "    spls = [i for i in spls if i not in sw and i != \"\"]\n",
    "    return spls"
   ]
  },
  {
   "cell_type": "code",
   "execution_count": 9,
   "metadata": {},
   "outputs": [
    {
     "name": "stdout",
     "output_type": "stream",
     "text": [
      "Unexpected exception formatting exception. Falling back to standard exception\n"
     ]
    },
    {
     "name": "stderr",
     "output_type": "stream",
     "text": [
      "Traceback (most recent call last):\n",
      "  File \"c:\\Users\\azhur\\AppData\\Local\\Programs\\Python\\Python310\\lib\\site-packages\\IPython\\core\\interactiveshell.py\", line 3398, in run_code\n",
      "    exec(code_obj, self.user_global_ns, self.user_ns)\n",
      "  File \"C:\\Users\\azhur\\AppData\\Local\\Temp\\ipykernel_35984\\1913021875.py\", line 12, in <cell line: 12>\n",
      "    for line in list_news:\n",
      "NameError: name 'list_news' is not defined\n",
      "\n",
      "During handling of the above exception, another exception occurred:\n",
      "\n",
      "Traceback (most recent call last):\n",
      "  File \"c:\\Users\\azhur\\AppData\\Local\\Programs\\Python\\Python310\\lib\\site-packages\\IPython\\core\\interactiveshell.py\", line 1993, in showtraceback\n",
      "    stb = self.InteractiveTB.structured_traceback(\n",
      "  File \"c:\\Users\\azhur\\AppData\\Local\\Programs\\Python\\Python310\\lib\\site-packages\\IPython\\core\\ultratb.py\", line 1118, in structured_traceback\n",
      "    return FormattedTB.structured_traceback(\n",
      "  File \"c:\\Users\\azhur\\AppData\\Local\\Programs\\Python\\Python310\\lib\\site-packages\\IPython\\core\\ultratb.py\", line 1012, in structured_traceback\n",
      "    return VerboseTB.structured_traceback(\n",
      "  File \"c:\\Users\\azhur\\AppData\\Local\\Programs\\Python\\Python310\\lib\\site-packages\\IPython\\core\\ultratb.py\", line 865, in structured_traceback\n",
      "    formatted_exception = self.format_exception_as_a_whole(etype, evalue, etb, number_of_lines_of_context,\n",
      "  File \"c:\\Users\\azhur\\AppData\\Local\\Programs\\Python\\Python310\\lib\\site-packages\\IPython\\core\\ultratb.py\", line 799, in format_exception_as_a_whole\n",
      "    self.get_records(etb, number_of_lines_of_context, tb_offset) if etb else []\n",
      "  File \"c:\\Users\\azhur\\AppData\\Local\\Programs\\Python\\Python310\\lib\\site-packages\\IPython\\core\\ultratb.py\", line 845, in get_records\n",
      "    style = stack_data.style_with_executing_node(style, \"bg:ansiyellow\")\n",
      "  File \"c:\\Users\\azhur\\AppData\\Local\\Programs\\Python\\Python310\\lib\\site-packages\\stack_data\\core.py\", line 424, in style_with_executing_node\n",
      "    class NewStyle(style):\n",
      "  File \"c:\\Users\\azhur\\AppData\\Local\\Programs\\Python\\Python310\\lib\\site-packages\\pygments\\style.py\", line 91, in __new__\n",
      "    ndef[4] = colorformat(styledef[3:])\n",
      "  File \"c:\\Users\\azhur\\AppData\\Local\\Programs\\Python\\Python310\\lib\\site-packages\\pygments\\style.py\", line 58, in colorformat\n",
      "    assert False, \"wrong color format %r\" % text\n",
      "AssertionError: wrong color format 'ansiyellow'\n"
     ]
    }
   ],
   "source": [
    "assert True\n",
    "\n",
    "# Preprocess for models fitting\n",
    "\n",
    "sentences = []\n",
    "\n",
    "morpher = MorphAnalyzer()\n",
    "sw = set(get_stop_words(\"ru\"))\n",
    "exclude = set(string.punctuation)\n",
    "c = 0\n",
    "\n",
    "for line in list_news:\n",
    "    spls = preprocess_txt(line)\n",
    "    sentences.append(spls)\n",
    "    c += 1\n",
    "    if c > 1000:\n",
    "        break"
   ]
  },
  {
   "cell_type": "code",
   "execution_count": 10,
   "metadata": {},
   "outputs": [],
   "source": [
    "sentences = [i for i in sentences if len(i) > 2]"
   ]
  },
  {
   "cell_type": "code",
   "execution_count": 11,
   "metadata": {},
   "outputs": [
    {
     "name": "stdout",
     "output_type": "stream",
     "text": [
      "Unexpected exception formatting exception. Falling back to standard exception\n"
     ]
    },
    {
     "name": "stderr",
     "output_type": "stream",
     "text": [
      "Traceback (most recent call last):\n",
      "  File \"c:\\Users\\azhur\\AppData\\Local\\Programs\\Python\\Python310\\lib\\site-packages\\IPython\\core\\interactiveshell.py\", line 3398, in run_code\n",
      "    exec(code_obj, self.user_global_ns, self.user_ns)\n",
      "  File \"C:\\Users\\azhur\\AppData\\Local\\Temp\\ipykernel_35984\\1460339799.py\", line 1, in <cell line: 1>\n",
      "    sentences[0][:20]\n",
      "IndexError: list index out of range\n",
      "\n",
      "During handling of the above exception, another exception occurred:\n",
      "\n",
      "Traceback (most recent call last):\n",
      "  File \"c:\\Users\\azhur\\AppData\\Local\\Programs\\Python\\Python310\\lib\\site-packages\\IPython\\core\\interactiveshell.py\", line 1993, in showtraceback\n",
      "    stb = self.InteractiveTB.structured_traceback(\n",
      "  File \"c:\\Users\\azhur\\AppData\\Local\\Programs\\Python\\Python310\\lib\\site-packages\\IPython\\core\\ultratb.py\", line 1118, in structured_traceback\n",
      "    return FormattedTB.structured_traceback(\n",
      "  File \"c:\\Users\\azhur\\AppData\\Local\\Programs\\Python\\Python310\\lib\\site-packages\\IPython\\core\\ultratb.py\", line 1012, in structured_traceback\n",
      "    return VerboseTB.structured_traceback(\n",
      "  File \"c:\\Users\\azhur\\AppData\\Local\\Programs\\Python\\Python310\\lib\\site-packages\\IPython\\core\\ultratb.py\", line 865, in structured_traceback\n",
      "    formatted_exception = self.format_exception_as_a_whole(etype, evalue, etb, number_of_lines_of_context,\n",
      "  File \"c:\\Users\\azhur\\AppData\\Local\\Programs\\Python\\Python310\\lib\\site-packages\\IPython\\core\\ultratb.py\", line 799, in format_exception_as_a_whole\n",
      "    self.get_records(etb, number_of_lines_of_context, tb_offset) if etb else []\n",
      "  File \"c:\\Users\\azhur\\AppData\\Local\\Programs\\Python\\Python310\\lib\\site-packages\\IPython\\core\\ultratb.py\", line 845, in get_records\n",
      "    style = stack_data.style_with_executing_node(style, \"bg:ansiyellow\")\n",
      "  File \"c:\\Users\\azhur\\AppData\\Local\\Programs\\Python\\Python310\\lib\\site-packages\\stack_data\\core.py\", line 424, in style_with_executing_node\n",
      "    class NewStyle(style):\n",
      "  File \"c:\\Users\\azhur\\AppData\\Local\\Programs\\Python\\Python310\\lib\\site-packages\\pygments\\style.py\", line 91, in __new__\n",
      "    ndef[4] = colorformat(styledef[3:])\n",
      "  File \"c:\\Users\\azhur\\AppData\\Local\\Programs\\Python\\Python310\\lib\\site-packages\\pygments\\style.py\", line 58, in colorformat\n",
      "    assert False, \"wrong color format %r\" % text\n",
      "AssertionError: wrong color format 'ansiyellow'\n"
     ]
    }
   ],
   "source": [
    "sentences[0][:20]"
   ]
  },
  {
   "cell_type": "code",
   "execution_count": 12,
   "metadata": {},
   "outputs": [
    {
     "name": "stdout",
     "output_type": "stream",
     "text": [
      "Object `Word2Vec` not found.\n"
     ]
    }
   ],
   "source": [
    "Word2Vec?"
   ]
  },
  {
   "cell_type": "code",
   "execution_count": 13,
   "metadata": {},
   "outputs": [
    {
     "name": "stdout",
     "output_type": "stream",
     "text": [
      "Unexpected exception formatting exception. Falling back to standard exception\n"
     ]
    },
    {
     "name": "stderr",
     "output_type": "stream",
     "text": [
      "Traceback (most recent call last):\n",
      "  File \"c:\\Users\\azhur\\AppData\\Local\\Programs\\Python\\Python310\\lib\\site-packages\\IPython\\core\\magics\\execution.py\", line 1316, in time\n",
      "    exec(code, glob, local_ns)\n",
      "  File \"<timed exec>\", line 1, in <module>\n",
      "NameError: name 'Word2Vec' is not defined\n",
      "\n",
      "During handling of the above exception, another exception occurred:\n",
      "\n",
      "Traceback (most recent call last):\n",
      "  File \"c:\\Users\\azhur\\AppData\\Local\\Programs\\Python\\Python310\\lib\\site-packages\\IPython\\core\\interactiveshell.py\", line 1993, in showtraceback\n",
      "    stb = self.InteractiveTB.structured_traceback(\n",
      "  File \"c:\\Users\\azhur\\AppData\\Local\\Programs\\Python\\Python310\\lib\\site-packages\\IPython\\core\\ultratb.py\", line 1118, in structured_traceback\n",
      "    return FormattedTB.structured_traceback(\n",
      "  File \"c:\\Users\\azhur\\AppData\\Local\\Programs\\Python\\Python310\\lib\\site-packages\\IPython\\core\\ultratb.py\", line 1012, in structured_traceback\n",
      "    return VerboseTB.structured_traceback(\n",
      "  File \"c:\\Users\\azhur\\AppData\\Local\\Programs\\Python\\Python310\\lib\\site-packages\\IPython\\core\\ultratb.py\", line 865, in structured_traceback\n",
      "    formatted_exception = self.format_exception_as_a_whole(etype, evalue, etb, number_of_lines_of_context,\n",
      "  File \"c:\\Users\\azhur\\AppData\\Local\\Programs\\Python\\Python310\\lib\\site-packages\\IPython\\core\\ultratb.py\", line 799, in format_exception_as_a_whole\n",
      "    self.get_records(etb, number_of_lines_of_context, tb_offset) if etb else []\n",
      "  File \"c:\\Users\\azhur\\AppData\\Local\\Programs\\Python\\Python310\\lib\\site-packages\\IPython\\core\\ultratb.py\", line 845, in get_records\n",
      "    style = stack_data.style_with_executing_node(style, \"bg:ansiyellow\")\n",
      "  File \"c:\\Users\\azhur\\AppData\\Local\\Programs\\Python\\Python310\\lib\\site-packages\\stack_data\\core.py\", line 424, in style_with_executing_node\n",
      "    class NewStyle(style):\n",
      "  File \"c:\\Users\\azhur\\AppData\\Local\\Programs\\Python\\Python310\\lib\\site-packages\\pygments\\style.py\", line 91, in __new__\n",
      "    ndef[4] = colorformat(styledef[3:])\n",
      "  File \"c:\\Users\\azhur\\AppData\\Local\\Programs\\Python\\Python310\\lib\\site-packages\\pygments\\style.py\", line 58, in colorformat\n",
      "    assert False, \"wrong color format %r\" % text\n",
      "AssertionError: wrong color format 'ansiyellow'\n"
     ]
    }
   ],
   "source": [
    "%%time\n",
    "modelW2V = Word2Vec(sentences=sentences, size=300, window=5, min_count=2)"
   ]
  },
  {
   "cell_type": "code",
   "execution_count": 14,
   "metadata": {},
   "outputs": [
    {
     "name": "stdout",
     "output_type": "stream",
     "text": [
      "Unexpected exception formatting exception. Falling back to standard exception\n"
     ]
    },
    {
     "name": "stderr",
     "output_type": "stream",
     "text": [
      "Traceback (most recent call last):\n",
      "  File \"c:\\Users\\azhur\\AppData\\Local\\Programs\\Python\\Python310\\lib\\site-packages\\IPython\\core\\interactiveshell.py\", line 3398, in run_code\n",
      "    exec(code_obj, self.user_global_ns, self.user_ns)\n",
      "  File \"C:\\Users\\azhur\\AppData\\Local\\Temp\\ipykernel_35984\\3222316426.py\", line 1, in <cell line: 1>\n",
      "    w2v_index = annoy.AnnoyIndex(300 ,'angular')\n",
      "NameError: name 'annoy' is not defined\n",
      "\n",
      "During handling of the above exception, another exception occurred:\n",
      "\n",
      "Traceback (most recent call last):\n",
      "  File \"c:\\Users\\azhur\\AppData\\Local\\Programs\\Python\\Python310\\lib\\site-packages\\IPython\\core\\interactiveshell.py\", line 1993, in showtraceback\n",
      "    stb = self.InteractiveTB.structured_traceback(\n",
      "  File \"c:\\Users\\azhur\\AppData\\Local\\Programs\\Python\\Python310\\lib\\site-packages\\IPython\\core\\ultratb.py\", line 1118, in structured_traceback\n",
      "    return FormattedTB.structured_traceback(\n",
      "  File \"c:\\Users\\azhur\\AppData\\Local\\Programs\\Python\\Python310\\lib\\site-packages\\IPython\\core\\ultratb.py\", line 1012, in structured_traceback\n",
      "    return VerboseTB.structured_traceback(\n",
      "  File \"c:\\Users\\azhur\\AppData\\Local\\Programs\\Python\\Python310\\lib\\site-packages\\IPython\\core\\ultratb.py\", line 865, in structured_traceback\n",
      "    formatted_exception = self.format_exception_as_a_whole(etype, evalue, etb, number_of_lines_of_context,\n",
      "  File \"c:\\Users\\azhur\\AppData\\Local\\Programs\\Python\\Python310\\lib\\site-packages\\IPython\\core\\ultratb.py\", line 799, in format_exception_as_a_whole\n",
      "    self.get_records(etb, number_of_lines_of_context, tb_offset) if etb else []\n",
      "  File \"c:\\Users\\azhur\\AppData\\Local\\Programs\\Python\\Python310\\lib\\site-packages\\IPython\\core\\ultratb.py\", line 845, in get_records\n",
      "    style = stack_data.style_with_executing_node(style, \"bg:ansiyellow\")\n",
      "  File \"c:\\Users\\azhur\\AppData\\Local\\Programs\\Python\\Python310\\lib\\site-packages\\stack_data\\core.py\", line 424, in style_with_executing_node\n",
      "    class NewStyle(style):\n",
      "  File \"c:\\Users\\azhur\\AppData\\Local\\Programs\\Python\\Python310\\lib\\site-packages\\pygments\\style.py\", line 91, in __new__\n",
      "    ndef[4] = colorformat(styledef[3:])\n",
      "  File \"c:\\Users\\azhur\\AppData\\Local\\Programs\\Python\\Python310\\lib\\site-packages\\pygments\\style.py\", line 58, in colorformat\n",
      "    assert False, \"wrong color format %r\" % text\n",
      "AssertionError: wrong color format 'ansiyellow'\n"
     ]
    }
   ],
   "source": [
    "w2v_index = annoy.AnnoyIndex(300 ,'angular')\n",
    "\n",
    "index_map = {}\n",
    "counter = 0\n",
    "\n",
    "for question in sentences:\n",
    "    n_w2v = 0\n",
    "    vector_w2v = np.zeros(300)\n",
    "    for word in question:\n",
    "        if word in modelW2V.wv:\n",
    "            vector_w2v += modelW2V.wv[word]\n",
    "            n_w2v += 1\n",
    "    if n_w2v > 0:\n",
    "        vector_w2v = vector_w2v / n_w2v\n",
    "    w2v_index.add_item(counter, vector_w2v)\n",
    "        \n",
    "    counter += 1\n",
    "    \n",
    "    if counter > 1000:\n",
    "        break\n",
    "\n",
    "w2v_index.build(10)\n"
   ]
  },
  {
   "cell_type": "code",
   "execution_count": 15,
   "metadata": {},
   "outputs": [],
   "source": [
    "def get_response(question, index, model, index_map, num_question):\n",
    "    question = preprocess_txt(question)\n",
    "    vector = np.zeros(300)\n",
    "    norm = 0\n",
    "    for word in question:\n",
    "        if word in model.wv:\n",
    "            vector += model.wv[word]\n",
    "            norm += 1\n",
    "    if norm > 0:\n",
    "        vector = vector / norm\n",
    "    answers = index.get_nns_by_vector(vector, num_question, )\n",
    "    return [list_news[i] for i in answers]"
   ]
  },
  {
   "cell_type": "code",
   "execution_count": 16,
   "metadata": {},
   "outputs": [
    {
     "name": "stdout",
     "output_type": "stream",
     "text": [
      "Unexpected exception formatting exception. Falling back to standard exception\n"
     ]
    },
    {
     "name": "stderr",
     "output_type": "stream",
     "text": [
      "Traceback (most recent call last):\n",
      "  File \"c:\\Users\\azhur\\AppData\\Local\\Programs\\Python\\Python310\\lib\\site-packages\\IPython\\core\\interactiveshell.py\", line 3398, in run_code\n",
      "    exec(code_obj, self.user_global_ns, self.user_ns)\n",
      "  File \"C:\\Users\\azhur\\AppData\\Local\\Temp\\ipykernel_35984\\2452185763.py\", line 2, in <cell line: 2>\n",
      "    get_response(TEXT, w2v_index, modelW2V, index_map, 1)\n",
      "NameError: name 'w2v_index' is not defined\n",
      "\n",
      "During handling of the above exception, another exception occurred:\n",
      "\n",
      "Traceback (most recent call last):\n",
      "  File \"c:\\Users\\azhur\\AppData\\Local\\Programs\\Python\\Python310\\lib\\site-packages\\IPython\\core\\interactiveshell.py\", line 1993, in showtraceback\n",
      "    stb = self.InteractiveTB.structured_traceback(\n",
      "  File \"c:\\Users\\azhur\\AppData\\Local\\Programs\\Python\\Python310\\lib\\site-packages\\IPython\\core\\ultratb.py\", line 1118, in structured_traceback\n",
      "    return FormattedTB.structured_traceback(\n",
      "  File \"c:\\Users\\azhur\\AppData\\Local\\Programs\\Python\\Python310\\lib\\site-packages\\IPython\\core\\ultratb.py\", line 1012, in structured_traceback\n",
      "    return VerboseTB.structured_traceback(\n",
      "  File \"c:\\Users\\azhur\\AppData\\Local\\Programs\\Python\\Python310\\lib\\site-packages\\IPython\\core\\ultratb.py\", line 865, in structured_traceback\n",
      "    formatted_exception = self.format_exception_as_a_whole(etype, evalue, etb, number_of_lines_of_context,\n",
      "  File \"c:\\Users\\azhur\\AppData\\Local\\Programs\\Python\\Python310\\lib\\site-packages\\IPython\\core\\ultratb.py\", line 799, in format_exception_as_a_whole\n",
      "    self.get_records(etb, number_of_lines_of_context, tb_offset) if etb else []\n",
      "  File \"c:\\Users\\azhur\\AppData\\Local\\Programs\\Python\\Python310\\lib\\site-packages\\IPython\\core\\ultratb.py\", line 845, in get_records\n",
      "    style = stack_data.style_with_executing_node(style, \"bg:ansiyellow\")\n",
      "  File \"c:\\Users\\azhur\\AppData\\Local\\Programs\\Python\\Python310\\lib\\site-packages\\stack_data\\core.py\", line 424, in style_with_executing_node\n",
      "    class NewStyle(style):\n",
      "  File \"c:\\Users\\azhur\\AppData\\Local\\Programs\\Python\\Python310\\lib\\site-packages\\pygments\\style.py\", line 91, in __new__\n",
      "    ndef[4] = colorformat(styledef[3:])\n",
      "  File \"c:\\Users\\azhur\\AppData\\Local\\Programs\\Python\\Python310\\lib\\site-packages\\pygments\\style.py\", line 58, in colorformat\n",
      "    assert False, \"wrong color format %r\" % text\n",
      "AssertionError: wrong color format 'ansiyellow'\n"
     ]
    }
   ],
   "source": [
    "TEXT = \"Хакерская группировка\"\n",
    "get_response(TEXT, w2v_index, modelW2V, index_map, 1)"
   ]
  },
  {
   "attachments": {},
   "cell_type": "markdown",
   "metadata": {},
   "source": [
    "Вывод: В принципе статьи подобраны согласно запрошенной теме."
   ]
  }
 ],
 "metadata": {
  "kernelspec": {
   "display_name": "Python 3",
   "language": "python",
   "name": "python3"
  },
  "language_info": {
   "codemirror_mode": {
    "name": "ipython",
    "version": 3
   },
   "file_extension": ".py",
   "mimetype": "text/x-python",
   "name": "python",
   "nbconvert_exporter": "python",
   "pygments_lexer": "ipython3",
   "version": "3.10.2"
  },
  "orig_nbformat": 4
 },
 "nbformat": 4,
 "nbformat_minor": 2
}
